Workbook

Sheet 읽는 법
B1: 서호팡팡수호대 밸런스 회의 자료
B2: 2026-09-28 실서버 게임의 실제 숫자예요. 게임 코드에서 그대로 옮겼어요.
B4: 시트 | C4: 무엇이 있나요
B5: 등급과 보급 | C5: 노말~전설 등급마다 필요한 개수, 보급 1번에 나오는 개수와 확률, 원하는 것을 모으려면 보급을 몇 번 해야 하는지, 보급권 얻는 법
B6: 친구(펫) | C6: 동물 친구 4마리의 능력(등급별 숫자)과 유니크부터 생기는 특수 능력
B7: 장비 | C7: 6칸 장비의 능력(등급별 숫자), 특수 효과, 같은 세트를 모으면 생기는 세트 효과
B8: 능력치(훈련) | C8: 공격력·체력·이동 속도 훈련 1~100단계의 효과와 코인 비용
B9: 코인 벌기 | C9: 단계와 난이도마다 성공 1번에 받는 코인, 훈련까지 며칠 걸리는지 계산기
B11: 색과 글씨
B12: 노말 | C12: 가장 낮은 등급
B13: 레어 | C13: 두 번째 등급
B14: 유니크 | C14: 세 번째 등급 · 특수 능력이 생겨요
B15: 에픽 | C15: 네 번째 등급 · 특수 능력이 강해져요
B16: 전설 | C16: 가장 높은 등급 · 특수 능력이 하나 더 생겨요
B17: 파란 글씨 칸 | C17: 회의에서 바꿔 볼 수 있는 숫자예요. 바꾸면 옆의 계산이 따라 바뀌어요. 여기서 바꿔도 실제 게임은 바뀌지 않아요.
B18: 검은 글씨 칸 | C18: 파란 글씨 숫자로 계산된 결과예요.
B20: 회의에서 이야기해 볼 것
B21: ① | C21: 친구 4마리 중 누구와 함께 출동하고 싶나요? 그 친구가 너무 세거나 약하지 않나요?
B22: ② | C22: 장비 하나를 레어(같은 장비 20개)로 만들려면 보급을 몇 번 해야 하나요? 알맞은가요, 너무 먼가요?
B23: ③ | C23: 보급 1번에 1개가 80%, 3개가 18%, 7개가 2%로 나와요. 이 운이 재미있나요, 억울한가요?
B24: ④ | C24: 훈련 비용과 효과는 알맞나요? 어려움에 도전하려면 공격·체력 15단계(1장), 20단계(2장)가 필요해요.
B25: ⑤ | C25: 하루에 받는 코인과 보급권은 충분한가요?

Sheet 등급과 보급
A1: 등급과 보급 — 같은 것을 모으면 강해져요
A2: 파란 글씨 칸은 바꿔 볼 수 있어요(게임은 바뀌지 않아요). 다른 시트의 등급별 숫자가 이 표를 따라 바뀌어요.
A4: ① 등급마다 필요한 개수와 힘
A5: 등급 | B5: 장비·친구 카드 개수 | C5: 파츠 개수 | D5: 장비·친구 힘 (전설 대비) | E5: 파츠 스킬 피해 보너스 | F5: 파츠 스킬 발동 간격
A6: 노말 | B6: 1 | C6: 1 | D6: 0.2 | E6: 0 | F6: 1
A7: 레어 | B7: 20 | C7: 3 | D7: 0.4 | E7: 0.1 | F7: 1
A8: 유니크 | B8: 40 | C8: 7 | D8: 0.6 | E8: 0.25 | F8: 0.95
A9: 에픽 | B9: 80 | C9: 25 | D9: 0.8 | E9: 0.45 | F9: 0.85
A10: 전설 | B10: 120 | C10: 80 | D10: 1 | E10: 0.8 | F10: 0.75
A11: 장비는 개수가 모이면 "합성" 버튼으로 등급을 올려요. 친구와 파츠는 개수가 모이면 저절로 올라가요. 발동 간격 75% = 스킬이 더 자주 나가요.
A13: ② 보급 1번에 나오는 개수 (파츠·장비·친구 모두 같아요)
A14: 나오는 개수 | B14: 확률
A15: 1 | B15: 0.8
A16: 3 | B16: 0.18
A17: 7 | B17: 0.02
A18: 확률 합계 (100%여야 해요) | B18: =SUM(B15:B17) -> 1
A19: 보급 1번에 평균 몇 개? | B19: =SUMPRODUCT(A15:A17,B15:B17) -> 1.48
A20: 무엇이 나올지는 아직 전설이 아닌 것 중에서 똑같은 확률로 골라요. "5번 보급"은 보급권 5장으로 5번을 한꺼번에 여는 것이고 확률은 같아요.
A22: ③ 원하는 것 하나를 그 등급까지 모으려면 보급 몇 번? (평균, 대략)
A23: 종류 | B23: 가짓수 | C23: 레어 | D23: 유니크 | E23: 에픽 | F23: 전설
A24: 장비 (내 캐릭터 장비 중 1개) | B24: 12 | C24: =ROUND(B$7*$B24/$B$19,0) -> 162 | D24: =ROUND(B$8*$B24/$B$19,0) -> 324 | E24: =ROUND(B$9*$B24/$B$19,0) -> 649 | F24: =ROUND(B$10*$B24/$B$19,0) -> 973
A25: 친구 (4마리 중 1마리) | B25: 4 | C25: =ROUND(B$7*$B25/$B$19,0) -> 54 | D25: =ROUND(B$8*$B25/$B$19,0) -> 108 | E25: =ROUND(B$9*$B25/$B$19,0) -> 216 | F25: =ROUND(B$10*$B25/$B$19,0) -> 324
A26: 파츠 (10종 중 1개) | B26: 10 | C26: =ROUND(C$7*$B26/$B$19,0) -> 20 | D26: =ROUND(C$8*$B26/$B$19,0) -> 47 | E26: =ROUND(C$9*$B26/$B$19,0) -> 169 | F26: =ROUND(C$10*$B26/$B$19,0) -> 541
A27: 예) 장비 하나를 레어(같은 장비 20개)로 만들려면 평균 약 160번. 보급할 때마다 다른 장비도 함께 모이니 장비 전체로는 더 빨리 강해져요. 전설이 된 것은 더 나오지 않아서 실제로는 조금 빨라요.
A29: ④ 보급권 얻는 법
A30: 방법 | B30: 보급권 | C30: 한도 | E30: 설명
A31: 쉬움·보통 성공 | B31: 1장 | C31: 같은 단계는 하루 2번까지 | E31: 여러 단계를 돌면 더 받아요
A32: 어려움 성공 | B32: 2장 | C32: 같은 단계는 하루 2번까지
A33: 대왕 단계(1-5·2-5) 처음 성공 | B33: +1장 | C33: 처음 한 번
A34: 150초 넘게 버티고 실패 2번 | B34: 1장 | C34: 하루 1장 | E34: 잘 못 깨도 조금씩 받아요
A35: 일일 미션 5개 | B35: 2장씩 (모두 10장) | C35: 하루 10장 | E35: 도전 1번 성공하기 · 환경 목표 1번 해내기 · 훈련·파츠 레벨 1번 올리기 · 도전 3번 성공하기 · 도전 5번 성공하기
A36: 코인으로 바꾸기 | B36: 1장 | C36: 하루 3번 | E36: 코인 300 → 450 → 600개 (바꿀수록 비싸져요)
A38: 처음 선물: 캐릭터를 고르면 무기 2개 · 1-1 처음 성공 파츠 1개 고르기 · 1-3 처음 성공 친구 카드 1장 고르기 · 1-5 처음 성공 친구 카드 3장 고르기
A39: 이용권: 매일 아침 8시에 10장. 성공하면 1장을 쓰고, 실패하면 쓰지 않아요 → 하루 10번까지 성공할 수 있어요.

Sheet 친구(펫)
A1: 동물 친구 4마리 — 함께 출동한 친구 1마리의 힘
A2: 전설(최대) 파란 글씨를 바꾸면 등급별 숫자가 따라 바뀌어요. 등급별 힘 비율은 "등급과 보급" 시트 ①의 장비·친구 힘.
A4: ① 친구 능력 (등급별)
A5: 번호 | B5: 친구 | C5: 역할 | D5: 능력 | E5: 전설(최대) | F5: 노말 | G5: 레어 | H5: 유니크 | I5: 에픽 | J5: 전설
A6: 1 | B6: 꼬북이 | C6: 생존 | D6: 받는 피해 | E6: -0.3 | F6: =$E6*'등급과 보급'!$D$6 -> -0.06 | G6: =$E6*'등급과 보급'!$D$7 -> -0.12 | H6: =$E6*'등급과 보급'!$D$8 -> -0.18 | I6: =$E6*'등급과 보급'!$D$9 -> -0.24 | J6: =$E6*'등급과 보급'!$D$10 -> -0.3
D7: 최대 체력 | E7: 0.3 | F7: =$E7*'등급과 보급'!$D$6 -> 0.06 | G7: =$E7*'등급과 보급'!$D$7 -> 0.12 | H7: =$E7*'등급과 보급'!$D$8 -> 0.18 | I7: =$E7*'등급과 보급'!$D$9 -> 0.24 | J7: =$E7*'등급과 보급'!$D$10 -> 0.3
D8: 1초마다 체력 회복 | E8: 0.02 | F8: =$E8*'등급과 보급'!$D$6 -> 0.004 | G8: =$E8*'등급과 보급'!$D$7 -> 0.008 | H8: =$E8*'등급과 보급'!$D$8 -> 0.012 | I8: =$E8*'등급과 보급'!$D$9 -> 0.016 | J8: =$E8*'등급과 보급'!$D$10 -> 0.02
A9: 2 | B9: 야옹이 | C9: 이동·공격 속도 | D9: 이동 속도 | E9: 0.3 | F9: =$E9*'등급과 보급'!$D$6 -> 0.06 | G9: =$E9*'등급과 보급'!$D$7 -> 0.12 | H9: =$E9*'등급과 보급'!$D$8 -> 0.18 | I9: =$E9*'등급과 보급'!$D$9 -> 0.24 | J9: =$E9*'등급과 보급'!$D$10 -> 0.3
D10: 공격 속도 | E10: 0.5 | F10: =$E10*'등급과 보급'!$D$6 -> 0.1 | G10: =$E10*'등급과 보급'!$D$7 -> 0.2 | H10: =$E10*'등급과 보급'!$D$8 -> 0.3 | I10: =$E10*'등급과 보급'!$D$9 -> 0.4 | J10: =$E10*'등급과 보급'!$D$10 -> 0.5
A11: 3 | B11: 수달이 | C11: 공격력·범위 | D11: 모든 스킬 피해 | E11: 0.5 | F11: =$E11*'등급과 보급'!$D$6 -> 0.1 | G11: =$E11*'등급과 보급'!$D$7 -> 0.2 | H11: =$E11*'등급과 보급'!$D$8 -> 0.3 | I11: =$E11*'등급과 보급'!$D$9 -> 0.4 | J11: =$E11*'등급과 보급'!$D$10 -> 0.5
D12: 스킬 범위 | E12: 0.3 | F12: =$E12*'등급과 보급'!$D$6 -> 0.06 | G12: =$E12*'등급과 보급'!$D$7 -> 0.12 | H12: =$E12*'등급과 보급'!$D$8 -> 0.18 | I12: =$E12*'등급과 보급'!$D$9 -> 0.24 | J12: =$E12*'등급과 보급'!$D$10 -> 0.3
A13: 4 | B13: 아기사슴 | C13: 새싹 경험치·코인 | D13: 새싹 경험치 | E13: 0.5 | F13: =$E13*'등급과 보급'!$D$6 -> 0.1 | G13: =$E13*'등급과 보급'!$D$7 -> 0.2 | H13: =$E13*'등급과 보급'!$D$8 -> 0.3 | I13: =$E13*'등급과 보급'!$D$9 -> 0.4 | J13: =$E13*'등급과 보급'!$D$10 -> 0.5
D14: 새싹 줍기 범위 | E14: 1.5 | F14: =$E14*'등급과 보급'!$D$6 -> 0.3 | G14: =$E14*'등급과 보급'!$D$7 -> 0.6 | H14: =$E14*'등급과 보급'!$D$8 -> 0.9 | I14: =$E14*'등급과 보급'!$D$9 -> 1.2 | J14: =$E14*'등급과 보급'!$D$10 -> 1.5
D15: 코인 획득 | E15: 0.5 | F15: =$E15*'등급과 보급'!$D$6 -> 0.1 | G15: =$E15*'등급과 보급'!$D$7 -> 0.2 | H15: =$E15*'등급과 보급'!$D$8 -> 0.3 | I15: =$E15*'등급과 보급'!$D$9 -> 0.4 | J15: =$E15*'등급과 보급'!$D$10 -> 0.5
A16: 받는 피해 -30% = 적에게 맞을 때 덜 아파요. 공격 속도 +50% = 1초에 공격을 1.5배 해요(공격 간격 약 33% 짧아짐). 코인 획득은 성공 보상 코인에 더해져요.
A18: ② 특수 능력 (유니크부터 생겨요)
A19: 친구 | C19: 특수 능력 | D19: 유니크 | F19: 에픽 | H19: 전설 (에픽 + 추가)
A20: 꼬북이 | C20: 등껍질 방패 | D20: 15초마다 보호막(최대 체력 10%) | F20: 10초마다 · 보호막 15% | H20: 판마다 1번 쓰러져도 일어남
A21: 야옹이 | C21: 바람 질주 | D21: 10초마다 3초 동안 공격 속도 +25% | F21: 7초마다(더 자주) | H21: 그 3초 동안 이동 속도도 +30%
A22: 수달이 | C22: 물방울 폭탄 | D22: 5초마다 적이 많은 곳에 물방울 폭탄(주변 적 모두 피해) | F22: 3.5초마다 · 폭탄 피해 1.5배 | H22: 물방울 폭탄 3개를 한꺼번에
A23: 아기사슴 | C23: 새싹 자석 | D23: 20초마다 화면의 새싹을 모두 끌어오기 | F23: 12초마다(더 자주) | H23: 끌어온 새싹 경험치 +50%
A25: ③ 친구 만나는 법
A26: • 1-3 처음 성공: 4마리 중 1마리 골라 카드 1장 · 1-5 처음 성공: 1마리 골라 카드 3장
A27: • 친구 보급(보급권 1장): 아직 전설이 아닌 친구 중 무작위 1마리 카드, 1·3·7장 (확률은 "등급과 보급" ②)
A28: • 같은 친구 카드를 모으면 등급이 저절로 올라가요: 노말 1장 · 레어 20장 · 유니크 40장 · 에픽 80장 · 전설 120장
A29: • 출동할 때 친구는 1마리만 함께 가요.

Sheet 장비
A1: 장비 — 6칸, 원거리·근거리 세트
A2: 호야와 민지의 같은 역할 장비는 이름·그림만 다르고 능력이 똑같아요. 전설(최대) 파란 글씨를 바꾸면 등급별 숫자가 따라 바뀌어요.
A4: ① 장비 능력 (등급별)
A5: 세트 | B5: 칸 | C5: 호야 장비 | D5: 민지 장비 | E5: 능력 | F5: 전설(최대) | G5: 노말 | H5: 레어 | I5: 유니크 | J5: 에픽 | K5: 전설
A6: 원거리 | B6: 투구 | C6: 야구 헬멧 | D6: 피구 머리띠 | E6: 치명타 확률 | F6: 0.3 | G6: =$F6*'등급과 보급'!$D$6 -> 0.06 | H6: =$F6*'등급과 보급'!$D$7 -> 0.12 | I6: =$F6*'등급과 보급'!$D$8 -> 0.18 | J6: =$F6*'등급과 보급'!$D$9 -> 0.24 | K6: =$F6*'등급과 보급'!$D$10 -> 0.3
B7: 갑옷 | C7: 야구 유니폼 | D7: 피구 체육복 | E7: 최대 체력 | F7: 0.6 | G7: =$F7*'등급과 보급'!$D$6 -> 0.12 | H7: =$F7*'등급과 보급'!$D$7 -> 0.24 | I7: =$F7*'등급과 보급'!$D$8 -> 0.36 | J7: =$F7*'등급과 보급'!$D$9 -> 0.48 | K7: =$F7*'등급과 보급'!$D$10 -> 0.6
B8: 신발 | C8: 야구 스파이크 | D8: 피구 운동화 | E8: 이동 속도 | F8: 0.3 | G8: =$F8*'등급과 보급'!$D$6 -> 0.06 | H8: =$F8*'등급과 보급'!$D$7 -> 0.12 | I8: =$F8*'등급과 보급'!$D$8 -> 0.18 | J8: =$F8*'등급과 보급'!$D$9 -> 0.24 | K8: =$F8*'등급과 보급'!$D$10 -> 0.3
B9: 장갑 | C9: 야구 글러브 | D9: 손목 보호대 | E9: 공격 속도 | F9: 0.5 | G9: =$F9*'등급과 보급'!$D$6 -> 0.1 | H9: =$F9*'등급과 보급'!$D$7 -> 0.2 | I9: =$F9*'등급과 보급'!$D$8 -> 0.3 | J9: =$F9*'등급과 보급'!$D$9 -> 0.4 | K9: =$F9*'등급과 보급'!$D$10 -> 0.5
B10: 목걸이 | C10: 우승 메달 목걸이 | D10: 호루라기 목걸이 | E10: 모든 피해 | F10: 0.5 | G10: =$F10*'등급과 보급'!$D$6 -> 0.1 | H10: =$F10*'등급과 보급'!$D$7 -> 0.2 | I10: =$F10*'등급과 보급'!$D$8 -> 0.3 | J10: =$F10*'등급과 보급'!$D$9 -> 0.4 | K10: =$F10*'등급과 보급'!$D$10 -> 0.5
B11: 무기 | C11: 강속구 야구 배트 | D11: 번개 피구공 | E11: 기본 무기 피해 | F11: 2 | G11: =$F11*'등급과 보급'!$D$6 -> 0.4 | H11: =$F11*'등급과 보급'!$D$7 -> 0.8 | I11: =$F11*'등급과 보급'!$D$8 -> 1.2 | J11: =$F11*'등급과 보급'!$D$9 -> 1.6 | K11: =$F11*'등급과 보급'!$D$10 -> 2
E12: 기본 무기 사거리 | F12: 0.6 | G12: =$F12*'등급과 보급'!$D$6 -> 0.12 | H12: =$F12*'등급과 보급'!$D$7 -> 0.24 | I12: =$F12*'등급과 보급'!$D$8 -> 0.36 | J12: =$F12*'등급과 보급'!$D$9 -> 0.48 | K12: =$F12*'등급과 보급'!$D$10 -> 0.6
A13: 근거리 | B13: 투구 | C13: 학생 모자 | D13: 리본 머리핀 | E13: 받는 피해 | F13: -0.3 | G13: =$F13*'등급과 보급'!$D$6 -> -0.06 | H13: =$F13*'등급과 보급'!$D$7 -> -0.12 | I13: =$F13*'등급과 보급'!$D$8 -> -0.18 | J13: =$F13*'등급과 보급'!$D$9 -> -0.24 | K13: =$F13*'등급과 보급'!$D$10 -> -0.3
B14: 갑옷 | C14: 교복 재킷 | D14: 교복 조끼 | E14: 최대 체력 | F14: 0.8 | G14: =$F14*'등급과 보급'!$D$6 -> 0.16 | H14: =$F14*'등급과 보급'!$D$7 -> 0.32 | I14: =$F14*'등급과 보급'!$D$8 -> 0.48 | J14: =$F14*'등급과 보급'!$D$9 -> 0.64 | K14: =$F14*'등급과 보급'!$D$10 -> 0.8
B15: 신발 | C15: 실내화 | D15: 교복 구두 | E15: 이동 속도 | F15: 0.3 | G15: =$F15*'등급과 보급'!$D$6 -> 0.06 | H15: =$F15*'등급과 보급'!$D$7 -> 0.12 | I15: =$F15*'등급과 보급'!$D$8 -> 0.18 | J15: =$F15*'등급과 보급'!$D$9 -> 0.24 | K15: =$F15*'등급과 보급'!$D$10 -> 0.3
B16: 장갑 | C16: 목장갑 | D16: 손목 밴드 | E16: 기본 무기 피해 | F16: 1 | G16: =$F16*'등급과 보급'!$D$6 -> 0.2 | H16: =$F16*'등급과 보급'!$D$7 -> 0.4 | I16: =$F16*'등급과 보급'!$D$8 -> 0.6 | J16: =$F16*'등급과 보급'!$D$9 -> 0.8 | K16: =$F16*'등급과 보급'!$D$10 -> 1
B17: 목걸이 | C17: 명찰 목걸이 | D17: 하트 명찰 목걸이 | E17: 1초마다 체력 회복 | F17: 0.03 | G17: =$F17*'등급과 보급'!$D$6 -> 0.006 | H17: =$F17*'등급과 보급'!$D$7 -> 0.012 | I17: =$F17*'등급과 보급'!$D$8 -> 0.018 | J17: =$F17*'등급과 보급'!$D$9 -> 0.024 | K17: =$F17*'등급과 보급'!$D$10 -> 0.03
B18: 무기 | C18: 목검 | D18: 왕 연필 | E18: 기본 무기 피해 | F18: 2 | G18: =$F18*'등급과 보급'!$D$6 -> 0.4 | H18: =$F18*'등급과 보급'!$D$7 -> 0.8 | I18: =$F18*'등급과 보급'!$D$8 -> 1.2 | J18: =$F18*'등급과 보급'!$D$9 -> 1.6 | K18: =$F18*'등급과 보급'!$D$10 -> 2
E19: 휘두르기 범위 | F19: 0.6 | G19: =$F19*'등급과 보급'!$D$6 -> 0.12 | H19: =$F19*'등급과 보급'!$D$7 -> 0.24 | I19: =$F19*'등급과 보급'!$D$8 -> 0.36 | J19: =$F19*'등급과 보급'!$D$9 -> 0.48 | K19: =$F19*'등급과 보급'!$D$10 -> 0.6
A20: 원거리 세트: 호야 야구복 · 민지 피구복 / 근거리 세트: 호야·민지 교복. 받는 피해 -30% = 덜 아파요. 공격 속도 +50% = 1초에 공격 1.5배.
A22: ② 특수 효과 (유니크부터)
A23: 세트 | B23: 칸 | C23: 이름 | D23: 유니크 | F23: 에픽 | I23: 전설 (에픽 + 추가)
A24: 원거리 | B24: 투구 | C24: 집중 | D24: 5초 동안 안 맞으면 다음 공격 치명타 확정 | F24: 3초만 안 맞아도 됨 | I24: 확정 치명타 피해 +50%
A25: 원거리 | B25: 갑옷 | C25: 든든 | D25: 체력 30% 아래로 떨어지면 3초 동안 받는 피해 -50%(30초에 1번) | F25: 20초에 1번(더 자주) | I25: 그때 체력 10% 회복
A26: 원거리 | B26: 신발 | C26: 도루 | D26: 8초마다 1초 동안 이동 속도 +40% | F26: 5초마다(더 자주) | I26: 그 1초 동안 적과 부딪히지 않음
A27: 원거리 | B27: 장갑 | C27: 캐치 | D27: 날아오는 적 탄 8초에 1개 잡기(대왕 탄 제외) | F27: 5초에 1개(더 자주) | I27: 잡은 탄을 되던져 적에게 피해
A28: 원거리 | B28: 목걸이 | C28: 응원 | D28: 대왕에게 주는 피해 +15% | F28: 대왕에게 주는 피해 +25%로 강해짐 | I28: 대왕 공격으로 받는 피해 -20%
A29: 원거리 | B29: 무기 | C29: 강속구 | D29: 5번째 공마다 강속구(피해 2배, 뚫고 감) | F29: 4번째 공마다(더 자주) | I29: 3번째 공마다 + 맞은 자리 작은 폭발
A30: 근거리 | B30: 투구 | C30: 침착 | D30: 10초마다 다음 피해 1번 막기 | F30: 7초마다(더 자주) | I30: 막을 때 주변 적 밀쳐내기
A31: 근거리 | B31: 갑옷 | C31: 버티기 | D31: 체력 30% 아래에서 받는 피해 -30% | F31: 받는 피해 -40%로 강해짐 | I31: 판마다 1번 쓰러져도 체력 절반으로 일어남
A32: 근거리 | B32: 신발 | C32: 굳건 | D32: 적에게 부딪혀 받는 피해 -15% | F32: 부딪혀 받는 피해 -25%로 강해짐 | I32: 부딪힌 적을 1초 느리게
A33: 근거리 | B33: 장갑 | C33: 흡수 | D33: 기본 무기로 적을 쓰러뜨리면 체력 0.5% 회복 | F33: 회복 1%로 강해짐 | I33: 10% 확률로 2배 회복
A34: 근거리 | B34: 목걸이 | C34: 반사 | D34: 부딪힌 적에게 받은 피해의 30% 되돌려 줌 | F34: 되돌려 주는 피해 50%로 강해짐 | I34: 되돌려 주는 피해 80% + 반사로 적 0.5초 멈춤
A35: 근거리 | B35: 무기 | C35: 회전 베기 | D35: 6번째 휘두르기마다 한 바퀴 베기(주변 전체) | F35: 5번째 휘두르기마다(더 자주) | I35: 4번째마다 + 범위 +30%
A37: ③ 세트 효과 (같은 세트를 여러 칸 끼우면, 등급과 상관없이)
A38: 세트 | C38: 2개 | F38: 4개 | I38: 6개
A39: 원거리 세트 | C39: 기본 무기 사거리 +15% · 이동 속도 +5% | F39: 모든 피해 +10% · 치명타 피해 +20% | I39: 기본 무기 공이 적 1명 더 뚫고 감 · 스킬이 적을 찾는 거리 +15%
A40: 근거리 세트 | C40: 최대 체력 +15% | F40: 받는 피해 -10% · 부딪혀 잃는 체력 상한 -15% | I40: 12초마다 보호막(최대 체력 12%) · 휘두르기가 적 탄을 없앰
A42: ④ 장비 얻는 법
A43: • 캐릭터(호야·민지)를 고르면 원거리·근거리 무기 1개씩 무료. 캐릭터는 한 번 고르면 바꿀 수 없어요(선생님만 바꿀 수 있음).
A44: • 장비 보급(보급권 1장): 내 캐릭터 장비 12종 중 아직 전설이 아닌 것 하나가 무작위로 1·3·7개.
...

Sheet 능력치(훈련)
A1: 기본 능력치(훈련) — 코인으로 한 단계씩, 최대 100단계
A2: 공격력·체력·이동 속도를 따로 올려요. 파란 글씨를 바꾸면 아래 표가 모두 따라 바뀌어요.
A4: 규칙 (바꿔 볼 수 있어요) | D4: 주요 단계 한눈에
A5: 공격력·체력 1단계당 + | B5: 0.03 | D5: 단계 | E5: 공격력 | F5: 체력 | G5: 이동 속도 | H5: 한 능력치 코인 | I5: 세 능력치 모두
A6: 이동 속도 1단계당 + (31단계까지) | B6: 0.005 | D6: 10 | E6: =B25 -> 0.27 | F6: =C25 -> 0.27 | G6: =D25 -> 0.045 | H6: =F25 -> 882 | I6: =G25 -> 2646
A7: 이동 속도 1단계당 + (31단계 뒤) | B7: 0.001 | D7: 15 | E7: =B30 -> 0.42 | F7: =C30 -> 0.42 | G7: =D30 -> 0.07 | H7: =F30 -> 1792 | I7: =G30 -> 5376
A8: 1→2단계 비용 (코인) | B8: 50 | D8: 20 | E8: =B35 -> 0.57 | F8: =C35 -> 0.57 | G8: =D35 -> 0.095 | H8: =F35 -> 3002 | I8: =G35 -> 9006
A9: 단계마다 늘어나는 비용 (코인) | B9: 12 | D9: 40 | E9: =B55 -> 1.17 | F9: =C55 -> 1.17 | G9: =D55 -> 0.159 | H9: =F55 -> 10842 | I9: =G55 -> 32526
A10: 최대 단계 | B10: 100 | D10: 60 | E10: =B75 -> 1.77 | F10: =C75 -> 1.77 | G10: =D75 -> 0.179 | H10: =F75 -> 23482 | I10: =G75 -> 70446
D11: 100 | E11: =B115 -> 2.97 | F11: =C115 -> 2.97 | G11: =D115 -> 0.219 | H11: =F115 -> 63162 | I11: =G115 -> 189486
D12: 어려움 도전 최소: 1장 공격·체력 15단계 · 2장 20단계(노랑). 어려움 권장: 공격·체력 40 · 이동 속도 20(주황).
A15: 단계 | B15: 공격력 | C15: 체력 | D15: 이동 속도 | E15: 다음 단계 비용 | F15: 이 단계까지 쓴 코인(한 능력치) | G15: 세 능력치 모두 이 단계
A16: 1 | B16: =($A16-1)*$B$5 -> 0 | C16: =($A16-1)*$B$5 -> 0 | D16: =MIN(($A16-1)*$B$6,30*$B$6)+MAX(0,$A16-31)*$B$7 -> 0 | E16: =IF($A16>=$B$10,"최대",$B$8+$B$9*($A16-1)) -> 50 | F16: 0 | G16: =F16*3 -> 0
A17: 2 | B17: =($A17-1)*$B$5 -> 0.03 | C17: =($A17-1)*$B$5 -> 0.03 | D17: =MIN(($A17-1)*$B$6,30*$B$6)+MAX(0,$A17-31)*$B$7 -> 0.005 | E17: =IF($A17>=$B$10,"최대",$B$8+$B$9*($A17-1)) -> 62 | F17: =F16+E16 -> 50 | G17: =F17*3 -> 150
A18: 3 | B18: =($A18-1)*$B$5 -> 0.06 | C18: =($A18-1)*$B$5 -> 0.06 | D18: =MIN(($A18-1)*$B$6,30*$B$6)+MAX(0,$A18-31)*$B$7 -> 0.01 | E18: =IF($A18>=$B$10,"최대",$B$8+$B$9*($A18-1)) -> 74 | F18: =F17+E17 -> 112 | G18: =F18*3 -> 336
A19: 4 | B19: =($A19-1)*$B$5 -> 0.09 | C19: =($A19-1)*$B$5 -> 0.09 | D19: =MIN(($A19-1)*$B$6,30*$B$6)+MAX(0,$A19-31)*$B$7 -> 0.015 | E19: =IF($A19>=$B$10,"최대",$B$8+$B$9*($A19-1)) -> 86 | F19: =F18+E18 -> 186 | G19: =F19*3 -> 558
A20: 5 | B20: =($A20-1)*$B$5 -> 0.12 | C20: =($A20-1)*$B$5 -> 0.12 | D20: =MIN(($A20-1)*$B$6,30*$B$6)+MAX(0,$A20-31)*$B$7 -> 0.02 | E20: =IF($A20>=$B$10,"최대",$B$8+$B$9*($A20-1)) -> 98 | F20: =F19+E19 -> 272 | G20: =F20*3 -> 816
A21: 6 | B21: =($A21-1)*$B$5 -> 0.15 | C21: =($A21-1)*$B$5 -> 0.15 | D21: =MIN(($A21-1)*$B$6,30*$B$6)+MAX(0,$A21-31)*$B$7 -> 0.025 | E21: =IF($A21>=$B$10,"최대",$B$8+$B$9*($A21-1)) -> 110 | F21: =F20+E20 -> 370 | G21: =F21*3 -> 1110
A22: 7 | B22: =($A22-1)*$B$5 -> 0.18 | C22: =($A22-1)*$B$5 -> 0.18 | D22: =MIN(($A22-1)*$B$6,30*$B$6)+MAX(0,$A22-31)*$B$7 -> 0.03 | E22: =IF($A22>=$B$10,"최대",$B$8+$B$9*($A22-1)) -> 122 | F22: =F21+E21 -> 480 | G22: =F22*3 -> 1440
A23: 8 | B23: =($A23-1)*$B$5 -> 0.21 | C23: =($A23-1)*$B$5 -> 0.21 | D23: =MIN(($A23-1)*$B$6,30*$B$6)+MAX(0,$A23-31)*$B$7 -> 0.035 | E23: =IF($A23>=$B$10,"최대",$B$8+$B$9*($A23-1)) -> 134 | F23: =F22+E22 -> 602 | G23: =F23*3 -> 1806
A24: 9 | B24: =($A24-1)*$B$5 -> 0.24 | C24: =($A24-1)*$B$5 -> 0.24 | D24: =MIN(($A24-1)*$B$6,30*$B$6)+MAX(0,$A24-31)*$B$7 -> 0.04 | E24: =IF($A24>=$B$10,"최대",$B$8+$B$9*($A24-1)) -> 146 | F24: =F23+E23 -> 736 | G24: =F24*3 -> 2208
A25: 10 | B25: =($A25-1)*$B$5 -> 0.27 | C25: =($A25-1)*$B$5 -> 0.27 | D25: =MIN(($A25-1)*$B$6,30*$B$6)+MAX(0,$A25-31)*$B$7 -> 0.045 | E25: =IF($A25>=$B$10,"최대",$B$8+$B$9*($A25-1)) -> 158 | F25: =F24+E24 -> 882 | G25: =F25*3 -> 2646
A26: 11 | B26: =($A26-1)*$B$5 -> 0.3 | C26: =($A26-1)*$B$5 -> 0.3 | D26: =MIN(($A26-1)*$B$6,30*$B$6)+MAX(0,$A26-31)*$B$7 -> 0.05 | E26: =IF($A26>=$B$10,"최대",$B$8+$B$9*($A26-1)) -> 170 | F26: =F25+E25 -> 1040 | G26: =F26*3 -> 3120
A27: 12 | B27: =($A27-1)*$B$5 -> 0.33 | C27: =($A27-1)*$B$5 -> 0.33 | D27: =MIN(($A27-1)*$B$6,30*$B$6)+MAX(0,$A27-31)*$B$7 -> 0.055 | E27: =IF($A27>=$B$10,"최대",$B$8+$B$9*($A27-1)) -> 182 | F27: =F26+E26 -> 1210 | G27: =F27*3 -> 3630
A28: 13 | B28: =($A28-1)*$B$5 -> 0.36 | C28: =($A28-1)*$B$5 -> 0.36 | D28: =MIN(($A28-1)*$B$6,30*$B$6)+MAX(0,$A28-31)*$B$7 -> 0.06 | E28: =IF($A28>=$B$10,"최대",$B$8+$B$9*($A28-1)) -> 194 | F28: =F27+E27 -> 1392 | G28: =F28*3 -> 4176
... A115: 100 | B115: =($A115-1)*$B$5 -> 2.97 | C115: =($A115-1)*$B$5 -> 2.97 | D115: =MIN(($A115-1)*$B$6,30*$B$6)+MAX(0,$A115-31)*$B$7 -> 0.219 | E115: =IF($A115>=$B$10,"최대",$B$8+$B$9*($A115-1)) -> 최대 | F115: =F114+E114 -> 63162 | G115: =F115*3 -> 189486

Sheet 코인 벌기
A1: 코인 벌기 — 성공 1번에 받는 코인
A2: 이미 성공한 단계를 다시 성공하고 환경 목표(쓰레기 줍기·밸브 잠그기)도 해낸 경우예요. 파란 글씨를 바꿔 볼 수 있어요.
A4: 규칙
A5: 기본 코인 (1-1) | B5: 120
A6: 단계마다 더해지는 코인 | B6: 10
A7: 환경 목표를 해내면 + | B7: 30
A8: 대왕 단계(1-5·2-5) 성공 + | B8: 60
A9: 처음 성공하면 한 번 더 + | B9: 120
A10: 쉬움 배율 | B10: 0.8
A11: 보통 배율 | B11: 1
A12: 어려움 배율 | B12: 2
A13: 아기사슴 전설: 코인 + | B13: 0.5
A15: 단계별 코인 (다시 성공 + 환경 목표)
A16: 단계 | B16: 번호 | C16: 이름 | D16: 쉬움 | E16: 보통 | F16: 어려움 | G16: 처음 성공(보통)
A17: 1-1 | B17: 1 | C17: 과자봉지 골목 | D17: =INT(($B$5+$B$6*($B17-1)+$B$7+IF(MOD($B17,5)=0,$B$8,0))*$B$10) -> 120 | E17: =INT(($B$5+$B$6*($B17-1)+$B$7+IF(MOD($B17,5)=0,$B$8,0))*$B$11) -> 150 | F17: =INT(($B$5+$B$6*($B17-1)+$B$7+IF(MOD($B17,5)=0,$B$8,0))*$B$12) -> 300 | G17: =INT((IF($B17<=2,INT(($B$5+$B$6*($B17-1))*0.6),$B$5+$B$6*($B17-1))+$B$7+IF(MOD($B17,5)=0,$B$8,0)+$B$9)*$B$11) -> 222
A18: 1-2 | B18: 2 | C18: 분리수거 놀이터 | D18: =INT(($B$5+$B$6*($B18-1)+$B$7+IF(MOD($B18,5)=0,$B$8,0))*$B$10) -> 128 | E18: =INT(($B$5+$B$6*($B18-1)+$B$7+IF(MOD($B18,5)=0,$B$8,0))*$B$11) -> 160 | F18: =INT(($B$5+$B$6*($B18-1)+$B$7+IF(MOD($B18,5)=0,$B$8,0))*$B$12) -> 320 | G18: =INT((IF($B18<=2,INT(($B$5+$B$6*($B18-1))*0.6),$B$5+$B$6*($B18-1))+$B$7+IF(MOD($B18,5)=0,$B$8,0)+$B$9)*$B$11) -> 228
A19: 1-3 | B19: 3 | C19: 바람 부는 공원 | D19: =INT(($B$5+$B$6*($B19-1)+$B$7+IF(MOD($B19,5)=0,$B$8,0))*$B$10) -> 136 | E19: =INT(($B$5+$B$6*($B19-1)+$B$7+IF(MOD($B19,5)=0,$B$8,0))*$B$11) -> 170 | F19: =INT(($B$5+$B$6*($B19-1)+$B$7+IF(MOD($B19,5)=0,$B$8,0))*$B$12) -> 340 | G19: =INT((IF($B19<=2,INT(($B$5+$B$6*($B19-1))*0.6),$B$5+$B$6*($B19-1))+$B$7+IF(MOD($B19,5)=0,$B$8,0)+$B$9)*$B$11) -> 290
A20: 1-4 | B20: 4 | C20: 다시 피는 꽃길 | D20: =INT(($B$5+$B$6*($B20-1)+$B$7+IF(MOD($B20,5)=0,$B$8,0))*$B$10) -> 144 | E20: =INT(($B$5+$B$6*($B20-1)+$B$7+IF(MOD($B20,5)=0,$B$8,0))*$B$11) -> 180 | F20: =INT(($B$5+$B$6*($B20-1)+$B$7+IF(MOD($B20,5)=0,$B$8,0))*$B$12) -> 360 | G20: =INT((IF($B20<=2,INT(($B$5+$B$6*($B20-1))*0.6),$B$5+$B$6*($B20-1))+$B$7+IF(MOD($B20,5)=0,$B$8,0)+$B$9)*$B$11) -> 300
A21: 1-5 | B21: 5 | C21: 쓰레기 대장 구출 | D21: =INT(($B$5+$B$6*($B21-1)+$B$7+IF(MOD($B21,5)=0,$B$8,0))*$B$10) -> 200 | E21: =INT(($B$5+$B$6*($B21-1)+$B$7+IF(MOD($B21,5)=0,$B$8,0))*$B$11) -> 250 | F21: =INT(($B$5+$B$6*($B21-1)+$B$7+IF(MOD($B21,5)=0,$B$8,0))*$B$12) -> 500 | G21: =INT((IF($B21<=2,INT(($B$5+$B$6*($B21-1))*0.6),$B$5+$B$6*($B21-1))+$B$7+IF(MOD($B21,5)=0,$B$8,0)+$B$9)*$B$11) -> 370
A22: 2-1 | B22: 6 | C22: 매캐한 공단 입구 | D22: =INT(($B$5+$B$6*($B22-1)+$B$7+IF(MOD($B22,5)=0,$B$8,0))*$B$10) -> 160 | E22: =INT(($B$5+$B$6*($B22-1)+$B$7+IF(MOD($B22,5)=0,$B$8,0))*$B$11) -> 200 | F22: =INT(($B$5+$B$6*($B22-1)+$B$7+IF(MOD($B22,5)=0,$B$8,0))*$B$12) -> 400 | G22: =INT((IF($B22<=2,INT(($B$5+$B$6*($B22-1))*0.6),$B$5+$B$6*($B22-1))+$B$7+IF(MOD($B22,5)=0,$B$8,0)+$B$9)*$B$11) -> 320
A23: 2-2 | B23: 7 | C23: 굴뚝 골목 | D23: =INT(($B$5+$B$6*($B23-1)+$B$7+IF(MOD($B23,5)=0,$B$8,0))*$B$10) -> 168 | E23: =INT(($B$5+$B$6*($B23-1)+$B$7+IF(MOD($B23,5)=0,$B$8,0))*$B$11) -> 210 | F23: =INT(($B$5+$B$6*($B23-1)+$B$7+IF(MOD($B23,5)=0,$B$8,0))*$B$12) -> 420 | G23: =INT((IF($B23<=2,INT(($B$5+$B$6*($B23-1))*0.6),$B$5+$B$6*($B23-1))+$B$7+IF(MOD($B23,5)=0,$B$8,0)+$B$9)*$B$11) -> 330
A24: 2-3 | B24: 8 | C24: 가스 탱크 공장 | D24: =INT(($B$5+$B$6*($B24-1)+$B$7+IF(MOD($B24,5)=0,$B$8,0))*$B$10) -> 176 | E24: =INT(($B$5+$B$6*($B24-1)+$B$7+IF(MOD($B24,5)=0,$B$8,0))*$B$11) -> 220 | F24: =INT(($B$5+$B$6*($B24-1)+$B$7+IF(MOD($B24,5)=0,$B$8,0))*$B$12) -> 440 | G24: =INT((IF($B24<=2,INT(($B$5+$B$6*($B24-1))*0.6),$B$5+$B$6*($B24-1))+$B$7+IF(MOD($B24,5)=0,$B$8,0)+$B$9)*$B$11) -> 340
A25: 2-4 | B25: 9 | C25: 매연 도로 | D25: =INT(($B$5+$B$6*($B25-1)+$B$7+IF(MOD($B25,5)=0,$B$8,0))*$B$10) -> 184 | E25: =INT(($B$5+$B$6*($B25-1)+$B$7+IF(MOD($B25,5)=0,$B$8,0))*$B$11) -> 230 | F25: =INT(($B$5+$B$6*($B25-1)+$B$7+IF(MOD($B25,5)=0,$B$8,0))*$B$12) -> 460 | G25: =INT((IF($B25<=2,INT(($B$5+$B$6*($B25-1))*0.6),$B$5+$B$6*($B25-1))+$B$7+IF(MOD($B25,5)=0,$B$8,0)+$B$9)*$B$11) -> 350
A26: 2-5 | B26: 10 | C26: 굴뚝 대왕의 공장 | D26: =INT(($B$5+$B$6*($B26-1)+$B$7+IF(MOD($B26,5)=0,$B$8,0))*$B$10) -> 240 | E26: =INT(($B$5+$B$6*($B26-1)+$B$7+IF(MOD($B26,5)=0,$B$8,0))*$B$11) -> 300 | F26: =INT(($B$5+$B$6*($B26-1)+$B$7+IF(MOD($B26,5)=0,$B$8,0))*$B$12) -> 600 | G26: =INT((IF($B26<=2,INT(($B$5+$B$6*($B26-1))*0.6),$B$5+$B$6*($B26-1))+$B$7+IF(MOD($B26,5)=0,$B$8,0)+$B$9)*$B$11) -> 420
A27: 1-1·1-2는 처음 성공 전에는 기본 코인이 60%예요. 실패하면 버틴 시간만큼 조금 받아요(최대 기본 코인의 60%). 아기사슴과 함께 가면 코인이 더 늘어요.
A29: 계산기: 훈련까지 며칠 걸릴까?
A30: 하루에 성공하는 횟수 | B30: 10
A31: 도는 단계 번호 (1~10) | B31: 3
A32: 난이도 (1 쉬움 · 2 보통 · 3 어려움) | B32: 2
A33: 목표 훈련 단계 | B33: 40
A34: 하루에 받는 코인 | B34: =B30*INDEX(D17:F26,B31,B32) -> 1700
A35: 한 능력치를 목표까지 걸리는 날 | B35: =ROUNDUP(INDEX('능력치(훈련)'!F16:F115,B33)/B34,0) -> 7
A36: 세 능력치 모두 목표까지 걸리는 날 | B36: =ROUNDUP(INDEX('능력치(훈련)'!G16:G115,B33)/B34,0) -> 20
A37: 코인은 파츠 레벨 올리기·보급권 바꾸기에도 써요. 이 계산은 코인을 훈련에만 쓴다고 본 거예요.
